<?xml version="1.0" ?>
<!-- =================================================================================== -->
<!-- |    This document was autogenerated by xacro from ../xacro/mini_pupper_description.urdf.xacro | -->
<!-- |    EDITING THIS FILE BY HAND IS NOT RECOMMENDED                                 | -->
<!-- =================================================================================== -->
<!-- 
    ############################################
    ######              MEMO              ######
    ############################################
    x = front
    y = left
    z = up
    
    Origin is placed at geometry center of the body 

    https://mymodelrobot.appspot.com/6312011906416640
-->
<robot name="mini_pupper">
  <material name="white">
    <color rgba="0.9 0.9 0.9 1.0"/>
  </material>
  <material name="black">
    <color rgba="0.2 0.2 0.2 1.0"/>
  </material>
  <material name="dark_grey">
    <color rgba="0.3 0.3 0.3 1.0"/>
  </material>
  <material name="grey">
    <color rgba="0.6 0.6 0.6 1.0"/>
  </material>
  <!-- 
    ############################################
    ######              BODY              ######
    ############################################
    -->
  <!--
    ********************************************
    ******              PARTS             ******
    ********************************************
    -->
  <link name="base_link">
    <!--body-->
    <visual>
      <geometry>
        <mesh filename="../meshes/base_link.stl" scale="1.0 1.0 1.0"/>
      </geometry>
      <origin rpy="0 0 0" xyz="0 0 -0.017"/>
      <material name="white"/>
    </visual>
    <collision>
      <geometry>
        <box size="0.180 0.060 0.045"/>
      </geometry>
      <origin rpy="0 0 0" xyz="0.008 0 0.005"/>
    </collision>
    <!--body-battery-holder-->
    <visual>
      <geometry>
        <box size="0.150 0.036 0.008"/>
      </geometry>
      <origin rpy="0 0 0" xyz="0.0 0.0 -0.020"/>
      <material name="black"/>
    </visual>
    <collision>
      <geometry>
        <box size="0.150 0.036 0.008"/>
      </geometry>
      <origin rpy="0 0 0" xyz="0.0 0.0 -0.020"/>
    </collision>
    <inertial>
      <origin rpy="0 0 0" xyz="0.0 0.0 0.0"/>
      <mass value="0.2"/>
      <inertia ixx="0.02" ixy="0.0" ixz="0.0" iyy="0.03" iyz="0.0" izz="0.03"/>
    </inertial>
  </link>
  <!-- 
    ############################################
    ######              LEG Front Right   ######
    ############################################
    -->
  <!--
        ********************************************
        ******              PARTS             ******
        ********************************************
        -->
  <link name="fr-pod">
    <visual>
      <geometry>
        <mesh filename="../meshes/fr1.stl" scale="1.0 1.0 1.0"/>
      </geometry>
      <origin rpy="0.0 1.57079 0.0" xyz="0 0 0"/>
      <material name="black"/>
    </visual>
    <collision>
      <geometry>
        <box size="0.031 0.030 0.038"/>
      </geometry>
      <origin rpy="0.0 0 0" xyz="0.006 0.0 -0.006"/>
    </collision>
    <inertial>
      <mass value="0.05"/>
      <inertia ixx="0.0003" ixy="0.0" ixz="0.0" iyy="0.0008" iyz="0.0" izz="0.0008"/>
    </inertial>
  </link>
  <link name="fr-femur">
    <visual>
      <geometry>
        <mesh filename="../meshes/fr2.stl" scale="1.0 1.0 1.0"/>
      </geometry>
      <origin rpy="1.57079 0.0 -1.57079" xyz="0 0 0"/>
      <material name="dark_grey"/>
    </visual>
    <collision>
      <geometry>
        <box size="0.054 0.007 0.002"/>
      </geometry>
      <origin rpy="0.0 0.0 0.0" xyz="0.025 0.0 0.0"/>
    </collision>
    <inertial>
      <mass value="0.02"/>
      <inertia ixx="0.0001" ixy="0.0" ixz="0.0" iyy="0.0001" iyz="0.0" izz="0.0001"/>
    </inertial>
  </link>
  <link name="fr-tibia">
    <visual>
      <geometry>
        <mesh filename="../meshes/fr3.stl" scale="1.0 1.0 1.0"/>
      </geometry>
      <origin rpy="1.57079 0.0 -1.57079" xyz="0.000 0 0"/>
      <material name="grey"/>
    </visual>
    <collision>
      <geometry>
        <box size="0.060 0.006 0.002"/>
      </geometry>
      <origin rpy="0 0 0" xyz="0.030 0 0"/>
    </collision>
    <inertial>
      <mass value="0.01"/>
      <inertia ixx="0.0001" ixy="0.0" ixz="0.0" iyy="0.0001" iyz="0.0" izz="0.0001"/>
    </inertial>
  </link>
  <link name="fr-foot"/>
  <!--
        ********************************************
        ******             JOINTS             ******
        ********************************************
        -->
  <joint name="fr-abd" type="revolute">
    <parent link="base_link"/>
    <child link="fr-pod"/>
    <origin rpy="0 -1.57079 0" xyz="0.059 -0.0235 0"/>
    <axis xyz="0 0 1"/>
    <limit effort="100" lower="-0.4" upper="0.4" velocity="1000"/>
  </joint>
  <joint name="fr-hips" type="revolute">
    <parent link="fr-pod"/>
    <child link="fr-femur"/>
    <origin rpy="-1.57079 1.57079 0" xyz="0.0 -0.019 0.0"/>
    <axis xyz="0 0 1"/>
    <limit effort="100" lower="0.0" upper="3.4" velocity="1000"/>
  </joint>
  <joint name="fr-knee" type="revolute">
    <parent link="fr-femur"/>
    <child link="fr-tibia"/>
    <origin rpy="0 0 0" xyz="0.050 0 -0.005"/>
    <axis xyz="0 0 1"/>
    <limit effort="100" lower="-2.8" upper="0.0" velocity="1000"/>
  </joint>
  <joint name="fr-foot" type="fixed">
    <parent link="fr-tibia"/>
    <child link="fr-foot"/>
    <origin rpy="0 0 0" xyz="0.060 0 0"/>
    <axis xyz="0 0 1"/>
  </joint>
  <!-- 
    ############################################
    ######              LEG Front Left   ######
    ############################################
    -->
  <!--
        ********************************************
        ******              PARTS             ******
        ********************************************
        -->
  <link name="fl-pod">
    <visual>
      <geometry>
        <mesh filename="../meshes/fl1.stl" scale="1.0 1.0 1.0"/>
      </geometry>
      <origin rpy="0.0 1.57079 0.0" xyz="0 0 0"/>
      <material name="black"/>
    </visual>
    <collision>
      <geometry>
        <box size="0.031 0.030 0.038"/>
      </geometry>
      <origin rpy="0.0 0 0" xyz="0.006 0.0 -0.006"/>
    </collision>
    <inertial>
      <mass value="0.05"/>
      <inertia ixx="0.0003" ixy="0.0" ixz="0.0" iyy="0.0008" iyz="0.0" izz="0.0008"/>
    </inertial>
  </link>
  <link name="fl-femur">
    <visual>
      <geometry>
        <mesh filename="../meshes/fl2.stl" scale="1.0 1.0 1.0"/>
      </geometry>
      <origin rpy="1.57079 0.0 -1.57079" xyz="0 0 0"/>
      <material name="dark_grey"/>
    </visual>
    <collision>
      <geometry>
        <box size="0.054 0.007 0.002"/>
      </geometry>
      <origin rpy="0.0 0.0 0.0" xyz="0.025 0.0 0.0"/>
    </collision>
    <inertial>
      <mass value="0.02"/>
      <inertia ixx="0.0001" ixy="0.0" ixz="0.0" iyy="0.0001" iyz="0.0" izz="0.0001"/>
    </inertial>
  </link>
  <link name="fl-tibia">
    <visual>
      <geometry>
        <mesh filename="../meshes/fl3.stl" scale="1.0 1.0 1.0"/>
      </geometry>
      <origin rpy="1.57079 0.0 -1.57079" xyz="0.000 0 0"/>
      <material name="grey"/>
    </visual>
    <collision>
      <geometry>
        <box size="0.060 0.006 0.002"/>
      </geometry>
      <origin rpy="0 0 0" xyz="0.030 0 0"/>
    </collision>
    <inertial>
      <mass value="0.01"/>
      <inertia ixx="0.0001" ixy="0.0" ixz="0.0" iyy="0.0001" iyz="0.0" izz="0.0001"/>
    </inertial>
  </link>
  <link name="fl-foot"/>
  <!--
        ********************************************
        ******             JOINTS             ******
        ********************************************
        -->
  <joint name="fl-abd" type="revolute">
    <parent link="base_link"/>
    <child link="fl-pod"/>
    <origin rpy="0 -1.57079 0" xyz="0.059 -0.0235 0"/>
    <axis xyz="0 0 1"/>
    <limit effort="100" lower="-0.4" upper="0.4" velocity="1000"/>
  </joint>
  <joint name="fl-hips" type="revolute">
    <parent link="fl-pod"/>
    <child link="fl-femur"/>
    <origin rpy="-1.57079 1.57079 0" xyz="0.0 -0.019 0.0"/>
    <axis xyz="0 0 1"/>
    <limit effort="100" lower="0.0" upper="3.4" velocity="1000"/>
  </joint>
  <joint name="fl-knee" type="revolute">
    <parent link="fl-femur"/>
    <child link="fl-tibia"/>
    <origin rpy="0 0 0" xyz="0.050 0 -0.005"/>
    <axis xyz="0 0 1"/>
    <limit effort="100" lower="-2.8" upper="0.0" velocity="1000"/>
  </joint>
  <joint name="fl-foot" type="fixed">
    <parent link="fl-tibia"/>
    <child link="fl-foot"/>
    <origin rpy="0 0 0" xyz="0.060 0 0"/>
    <axis xyz="0 0 1"/>
  </joint>
  <!-- 
    ############################################
    ######              LEG Rear Right   ######
    ############################################
    -->
  <!--
        ********************************************
        ******              PARTS             ******
        ********************************************
        -->
  <link name="rr-pod">
    <visual>
      <geometry>
        <mesh filename="../meshes/rr1.stl" scale="1.0 1.0 1.0"/>
      </geometry>
      <origin rpy="0.0 1.57079 0.0" xyz="0 0 0"/>
      <material name="black"/>
    </visual>
    <collision>
      <geometry>
        <box size="0.031 0.030 0.038"/>
      </geometry>
      <origin rpy="0.0 0 0" xyz="0.006 0.0 -0.006"/>
    </collision>
    <inertial>
      <mass value="0.05"/>
      <inertia ixx="0.0003" ixy="0.0" ixz="0.0" iyy="0.0008" iyz="0.0" izz="0.0008"/>
    </inertial>
  </link>
  <link name="rr-femur">
    <visual>
      <geometry>
        <mesh filename="../meshes/rr2.stl" scale="1.0 1.0 1.0"/>
      </geometry>
      <origin rpy="1.57079 0.0 -1.57079" xyz="0 0 0"/>
      <material name="dark_grey"/>
    </visual>
    <collision>
      <geometry>
        <box size="0.054 0.007 0.002"/>
      </geometry>
      <origin rpy="0.0 0.0 0.0" xyz="0.025 0.0 0.0"/>
    </collision>
    <inertial>
      <mass value="0.02"/>
      <inertia ixx="0.0001" ixy="0.0" ixz="0.0" iyy="0.0001" iyz="0.0" izz="0.0001"/>
    </inertial>
  </link>
  <link name="rr-tibia">
    <visual>
      <geometry>
        <mesh filename="../meshes/rr3.stl" scale="1.0 1.0 1.0"/>
      </geometry>
      <origin rpy="1.57079 0.0 -1.57079" xyz="0.000 0 0"/>
      <material name="grey"/>
    </visual>
    <collision>
      <geometry>
        <box size="0.060 0.006 0.002"/>
      </geometry>
      <origin rpy="0 0 0" xyz="0.030 0 0"/>
    </collision>
    <inertial>
      <mass value="0.01"/>
      <inertia ixx="0.0001" ixy="0.0" ixz="0.0" iyy="0.0001" iyz="0.0" izz="0.0001"/>
    </inertial>
  </link>
  <link name="rr-foot"/>
  <!--
        ********************************************
        ******             JOINTS             ******
        ********************************************
        -->
  <joint name="rr-abd" type="revolute">
    <parent link="base_link"/>
    <child link="rr-pod"/>
    <origin rpy="0 -1.57079 0" xyz="0.059 -0.0235 0"/>
    <axis xyz="0 0 1"/>
    <limit effort="100" lower="-0.4" upper="0.4" velocity="1000"/>
  </joint>
  <joint name="rr-hips" type="revolute">
    <parent link="rr-pod"/>
    <child link="rr-femur"/>
    <origin rpy="-1.57079 1.57079 0" xyz="0.0 -0.019 0.0"/>
    <axis xyz="0 0 1"/>
    <limit effort="100" lower="0.0" upper="3.4" velocity="1000"/>
  </joint>
  <joint name="rr-knee" type="revolute">
    <parent link="rr-femur"/>
    <child link="rr-tibia"/>
    <origin rpy="0 0 0" xyz="0.050 0 -0.005"/>
    <axis xyz="0 0 1"/>
    <limit effort="100" lower="-2.8" upper="0.0" velocity="1000"/>
  </joint>
  <joint name="rr-foot" type="fixed">
    <parent link="rr-tibia"/>
    <child link="rr-foot"/>
    <origin rpy="0 0 0" xyz="0.060 0 0"/>
    <axis xyz="0 0 1"/>
  </joint>
  <!-- 
    ############################################
    ######              Leg Rear Left    ######
    ############################################
    -->
  <!--
        ********************************************
        ******              PARTS             ******
        ********************************************
        -->
  <link name="rl-pod">
    <visual>
      <geometry>
        <mesh filename="../meshes/rl1.stl" scale="1.0 1.0 1.0"/>
      </geometry>
      <origin rpy="0.0 1.57079 0.0" xyz="0 0 0"/>
      <material name="black"/>
    </visual>
    <collision>
      <geometry>
        <box size="0.031 0.030 0.038"/>
      </geometry>
      <origin rpy="0.0 0 0" xyz="0.006 0.0 -0.006"/>
    </collision>
    <inertial>
      <mass value="0.05"/>
      <inertia ixx="0.0003" ixy="0.0" ixz="0.0" iyy="0.0008" iyz="0.0" izz="0.0008"/>
    </inertial>
  </link>
  <link name="rl-femur">
    <visual>
      <geometry>
        <mesh filename="../meshes/rl2.stl" scale="1.0 1.0 1.0"/>
      </geometry>
      <origin rpy="1.57079 0.0 -1.57079" xyz="0 0 0"/>
      <material name="dark_grey"/>
    </visual>
    <collision>
      <geometry>
        <box size="0.054 0.007 0.002"/>
      </geometry>
      <origin rpy="0.0 0.0 0.0" xyz="0.025 0.0 0.0"/>
    </collision>
    <inertial>
      <mass value="0.02"/>
      <inertia ixx="0.0001" ixy="0.0" ixz="0.0" iyy="0.0001" iyz="0.0" izz="0.0001"/>
    </inertial>
  </link>
  <link name="rl-tibia">
    <visual>
      <geometry>
        <mesh filename="../meshes/rl3.stl" scale="1.0 1.0 1.0"/>
      </geometry>
      <origin rpy="1.57079 0.0 -1.57079" xyz="0.000 0 0"/>
      <material name="grey"/>
    </visual>
    <collision>
      <geometry>
        <box size="0.060 0.006 0.002"/>
      </geometry>
      <origin rpy="0 0 0" xyz="0.030 0 0"/>
    </collision>
    <inertial>
      <mass value="0.01"/>
      <inertia ixx="0.0001" ixy="0.0" ixz="0.0" iyy="0.0001" iyz="0.0" izz="0.0001"/>
    </inertial>
  </link>
  <link name="rl-foot"/>
  <!--
        ********************************************
        ******             JOINTS             ******
        ********************************************
        -->
  <joint name="rl-abd" type="revolute">
    <parent link="base_link"/>
    <child link="rl-pod"/>
    <origin rpy="0 -1.57079 0" xyz="0.059 -0.0235 0"/>
    <axis xyz="0 0 1"/>
    <limit effort="100" lower="-0.4" upper="0.4" velocity="1000"/>
  </joint>
  <joint name="rl-hips" type="revolute">
    <parent link="rl-pod"/>
    <child link="rl-femur"/>
    <origin rpy="-1.57079 1.57079 0" xyz="0.0 -0.019 0.0"/>
    <axis xyz="0 0 1"/>
    <limit effort="100" lower="0.0" upper="3.4" velocity="1000"/>
  </joint>
  <joint name="rl-knee" type="revolute">
    <parent link="rl-femur"/>
    <child link="rl-tibia"/>
    <origin rpy="0 0 0" xyz="0.050 0 -0.005"/>
    <axis xyz="0 0 1"/>
    <limit effort="100" lower="-2.8" upper="0.0" velocity="1000"/>
  </joint>
  <joint name="rl-foot" type="fixed">
    <parent link="rl-tibia"/>
    <child link="rl-foot"/>
    <origin rpy="0 0 0" xyz="0.060 0 0"/>
    <axis xyz="0 0 1"/>
  </joint>
  <!-- 
    ############################################
    ######               Accessories      ######
    ############################################
    -->
</robot>
